<?xml version='1.0'?>

<robot name="my_robot" xmlns:xacro="http://www.ros.org/wiki/xacro">
 <xacro:include filename="$(find my_robot)/urdf/my_robot.gazebo" />
  <link name="robot_footprint"></link>

  <!--Joints -->
  <joint name="robot_footprint_joint" type="fixed">
    <origin xyz="0 0 0" rpy="0 0 0" />
    <parent link="robot_footprint"/>
    <child link="chassis" />
  </joint>

  <joint name="body_part_front_joint" type="fixed">
    <origin xyz="0.39 0 0.25" rpy="0 0 0"/>
    <child link="body_part_front"/>
    <parent link="chassis"/>
    <axis xyz="0 1 0" rpy="0 0 0"/>
  </joint>

  <joint name="body_part_back_joint" type="fixed">
    <origin xyz="-0.39 0 0.25" rpy="0 0 0"/>
    <child link="body_part_back"/>
    <parent link="chassis"/>
    <axis xyz="0 1 0" rpy="0 0 0"/>
  </joint>

  <joint name="body_part_divider_joint" type="fixed">
    <origin xyz="0 0 0.25" rpy="0 0 0"/>
    <child link="body_part_divider"/>
    <parent link="chassis"/>
    <axis xyz="0 1 0" rpy="0 0 0"/>
  </joint>

  <joint name="body_part_roof_joint" type="fixed">
    <origin xyz="0 0 0.46" rpy="0 0 0"/>
    <child link="body_part_roof"/>
    <parent link="chassis"/>
    <axis xyz="0 1 0" rpy="0 0 0"/>
  </joint>

  <joint type="continuous" name="front_left_wheel_joint">
    <origin xyz="0.2 0.3 0" rpy="0 0 0"/>
    <child link="left_front_wheel"/>
    <parent link="chassis"/>
    <axis xyz="0 1 0" rpy="0 0 0"/>
    <limit effort="10000" velocity="1000"/>
    <dynamics damping="1.0" friction="1.0"/>
  </joint>

  <joint type="continuous" name="back_left_wheel_joint">
    <origin xyz="-0.2 0.3 0" rpy="0 0 0"/>
    <child link="left_back_wheel"/>
    <parent link="chassis"/>
    <axis xyz="0 1 0" rpy="0 0 0"/>
    <limit effort="10000" velocity="1000"/>
    <dynamics damping="1.0" friction="1.0"/>
  </joint>

  <joint type="continuous" name="front_right_wheel_joint">
    <origin xyz="0.2 -0.3 0" rpy="0 0 0"/>
    <child link="right_front_wheel"/>
    <parent link="chassis"/>
    <axis xyz="0 1 0" rpy="0 0 0"/>
    <limit effort="10000" velocity="1000"/>
    <dynamics damping="1.0" friction="1.0"/>
  </joint>

  <joint type="continuous" name="back_right_wheel_joint">
    <origin xyz="-0.2 -0.3 0" rpy="0 0 0"/>
    <child link="right_back_wheel"/>
    <parent link="chassis"/>
    <axis xyz="0 1 0" rpy="0 0 0"/>
    <limit effort="10000" velocity="1000"/>
    <dynamics damping="1.0" friction="1.0"/>
  </joint>

  <joint name="camera_joint" type="fixed">
    <origin xyz="0.035 0 0.15" rpy="0 0 0"/>
    <child link="camera"/>
    <parent link="body_part_front"/>
    <axis xyz="0 1 0" rpy="0 0 0"/>
  </joint>

  <joint name="hokuyo_joint" type="fixed">
    <origin xyz="0.3 0 0.045" rpy="0 0 0"/>
    <child link="hokuyo"/>
    <parent link="body_part_roof"/>
    <axis xyz="0 1 0" rpy="0 0 0"/>
  </joint>

  <!--Links-->
  <link name='chassis'>
    <pose>0 0 0.1 0 0 0</pose>
    <!--Robot Gross weight: 36kg or 80 pounds
    Chassis weight: 10kg
    Wheel weights: 3kg each and 12kg in total
    Body weight: 14kg
    - Body front part: 2.5kg
    - Body back part: 2.5kg
    - Body divider part: 4kg
    - Body roof part: 5kg --> 
    <inertial> 
      <mass value="10.0"/> 
      <origin xyz="0.0 0 0" rpy=" 0 0 0"/>
      <inertia 
          ixx="0.1" ixy="0" ixz="0" 
          iyy="0.1" iyz="0"
          izz="0.1"
      />
    </inertial>

    <collision name='collision'>
      <origin xyz="0 0 0" rpy=" 0 0 0"/> 
      <geometry>
        <box size=".8 .5 .1"/>
      </geometry>
    </collision>

    <visual name='chassis_visual'>
      <origin xyz="0 0 0" rpy=" 0 0 0"/>
      <geometry>
        <box size=".8 .5 .1"/>
      </geometry>
    </visual>
  </link>
  
  <!--Links-->
  <link name='body_part_front'>
    <pose>0 0 0.1 0 0 0</pose>

    <inertial> 
      <mass value="2.5"/> 
      <origin xyz="0.0 0 0" rpy=" 0 0 0"/>
      <inertia 
          ixx="0.1" ixy="0" ixz="0" 
          iyy="0.1" iyz="0"
          izz="0.1"
      />
    </inertial>

    <collision name='body_part_front_collision'>
      <origin xyz="0 0 0" rpy=" 0 0 0"/> 
      <geometry>
        <box size=".02 .5 .4"/>
      </geometry>
    </collision>

    <visual name='body_part_front_visual'>
      <origin xyz="0 0 0" rpy=" 0 0 0"/>
      <geometry>
        <box size=".02 .5 .4"/>
      </geometry>
    </visual>
  </link>

  <link name='body_part_back'>
    <pose>0 0 0.1 0 0 0</pose>

    <inertial> 
      <mass value="2.5"/> 
      <origin xyz="0.0 0 0" rpy=" 0 0 0"/>
      <inertia 
          ixx="0.1" ixy="0" ixz="0" 
          iyy="0.1" iyz="0"
          izz="0.1"
      />
    </inertial>

    <collision name='body_part_back_collision'>
      <origin xyz="0 0 0" rpy=" 0 0 0"/> 
      <geometry>
        <box size=".02 .5 .4"/>
      </geometry>
    </collision>

    <visual name='body_part_back_visual'>
      <origin xyz="0 0 0" rpy=" 0 0 0"/>
      <geometry>
        <box size=".02 .5 .4"/>
      </geometry>
    </visual>
  </link>

  <link name='body_part_divider'>
    <pose>0 0 0.1 0 0 0</pose>

    <inertial> 
      <mass value="4.0"/> 
      <origin xyz="0.0 0 0" rpy=" 0 0 0"/>
      <inertia 
          ixx="0.1" ixy="0" ixz="0" 
          iyy="0.1" iyz="0"
          izz="0.1"
      />
    </inertial>

    <collision name='body_part_divider_collision'>
      <origin xyz="0 0 0" rpy=" 0 0 0"/> 
      <geometry>
        <box size=".76 .02 .4"/>
      </geometry>
    </collision>

    <visual name='body_part_divider_visual'>
      <origin xyz="0 0 0" rpy=" 0 0 0"/>
      <geometry>
        <box size=".76 .02 .4"/>
      </geometry>
    </visual>

  </link>
    <link name='body_part_roof'>
    <pose>0 0 0.1 0 0 0</pose>

    <inertial> 
      <mass value="5.0"/> 
      <origin xyz="0.0 0 0" rpy=" 0 0 0"/>
      <inertia 
          ixx="0.1" ixy="0" ixz="0" 
          iyy="0.1" iyz="0"
          izz="0.1"
      />
    </inertial>

    <collision name='body_part_roof_collision'>
      <origin xyz="0 0 0" rpy=" 0 0 0"/> 
      <geometry>
        <box size=".8 .5 .02"/>
      </geometry>
    </collision>

    <visual name='body_part_roof_visual'>
      <origin xyz="0 0 0" rpy=" 0 0 0"/>
      <geometry>
        <box size=".8 .5 .02"/>
      </geometry>
    </visual>
  </link>

  <!--Left Front Wheel-->
  <link name='left_front_wheel'> 
    <pose>0 0 0 0 1.5707 1.5707</pose>

    <inertial>
      <mass value="3"/>
      <origin xyz="0 0 0" rpy=" 0 1.5707 1.5707"/>
      <inertia
          ixx="0.1" ixy="0" ixz="0"
          iyy="0.1" iyz="0"
          izz="0.1"
      />
    </inertial>

    <collision name='left_front_wheel_collision'>
      <origin xyz="0 0 0" rpy=" 0 1.5707 1.5707"/>
      <geometry>
        <cylinder radius="0.1" length="0.06"/>
      </geometry>
    </collision>

    <visual name='left_front_wheel_visual'>
      <origin xyz="0 0 0" rpy=" 0 1.5707 1.5707"/>
      <geometry>
        <cylinder radius="0.1" length="0.06"/>
      </geometry>
    </visual>
  </link>

  <!-- Left Rear Wheel-->
    <link name='left_back_wheel'> 
    <pose>0 0 0 0 1.5707 1.5707</pose>

    <inertial>
      <mass value="3"/>
      <origin xyz="0 0 0" rpy=" 0 1.5707 1.5707"/>
      <inertia
          ixx="0.1" ixy="0" ixz="0"
          iyy="0.1" iyz="0"
          izz="0.1"
      />
    </inertial>

    <collision name='left_back_wheel_collision'>
      <origin xyz="0 0 0" rpy=" 0 1.5707 1.5707"/>
      <geometry>
        <cylinder radius="0.1" length="0.06"/>
      </geometry>
    </collision>

    <visual name='left_back_wheel_visual'>
      <origin xyz="0 0 0" rpy=" 0 1.5707 1.5707"/>
      <geometry>
        <cylinder radius="0.1" length="0.06"/>
      </geometry>
    </visual>
  </link>

  <!--Right Front Wheel-->
  <link name='right_front_wheel'>
    <pose>0 0 0 0 1.5707 1.5707</pose>

    <inertial>
      <mass value="3"/>
      <origin xyz="0.0 0 0" rpy=" 0 1.5707 1.5707"/>
      <inertia
          ixx="0.1" ixy="0" ixz="0"
          iyy="0.1" iyz="0"
          izz="0.1"
      />
    </inertial>

   <collision name='right_front_wheel_collision'>
      <origin xyz="0 0 0" rpy=" 0 1.5707 1.5707"/>
      <geometry>
        <cylinder radius="0.1" length="0.06"/>
      </geometry>
    </collision>

    <visual name='right_front_wheel_visual'>
      <origin xyz="0 0 0" rpy=" 0 1.5707 1.5707"/>
      <geometry>
        <cylinder radius="0.1" length="0.06"/>
      </geometry>
    </visual> 
  </link>

  <!--Right Rear Wheel-->
  <link name='right_back_wheel'>
    <pose>0 0 0 0 1.5707 1.5707</pose>

    <inertial>
      <mass value="3"/>
      <origin xyz="0.0 0 0" rpy=" 0 1.5707 1.5707"/>
      <inertia
          ixx="0.1" ixy="0" ixz="0"
          iyy="0.1" iyz="0"
          izz="0.1"
      />
    </inertial>

   <collision name='right_back_wheel_collision'>
      <origin xyz="0 0 0" rpy=" 0 1.5707 1.5707"/>
      <geometry>
        <cylinder radius="0.1" length="0.06"/>
      </geometry>
    </collision>

    <visual name='right_back_wheel_visual'>
      <origin xyz="0 0 0" rpy=" 0 1.5707 1.5707"/>
      <geometry>
        <cylinder radius="0.1" length="0.06"/>
      </geometry>
    </visual> 
  </link>

  <link name='camera'>
    <pose>0 0 0 0 0 0</pose>

    <inertial>
      <mass value="0.1"/>
      <origin xyz="0 0 0" rpy=" 0 0 0"/>
      <inertia
          ixx="1e-6" ixy="0" ixz="0"
          iyy="1e-6" iyz="0"
          izz="1e-6"
      />
    </inertial>

    <collision name='camera_collision'>
      <origin xyz="0 0 0" rpy=" 0 0 0"/>
      <geometry>
        <box size="0.05 0.05 0.05"/>
      </geometry>
    </collision>

    <visual name='camera_visual'>
      <origin xyz="0 0 0" rpy=" 0 0 0"/>
      <geometry>
        <box size="0.05 0.05 0.05"/>
      </geometry>
    </visual> 
  </link>

  <link name='hokuyo'>
    <pose>0 0 0 0 0 0</pose>

    <inertial>
      <mass value="1e-5"/>
      <origin xyz="0 0 0" rpy=" 0 0 0"/>
      <inertia
          ixx="1e-6" ixy="0" ixz="0"
          iyy="1e-6" iyz="0"
          izz="1e-6"
      />
    </inertial>

    <collision name='hokuyo_collision'>
      <origin xyz="0 0 0" rpy=" 0 0 0"/>
      <geometry>
        <box size="0.1 0.1 0.1"/>
      </geometry>
    </collision>

    <visual name='hokuyo_visual'>
      <origin xyz="0 0 0" rpy=" 0 0 0"/>
      <geometry>
        <mesh filename="package://my_robot/meshes/hokuyo.dae"/>
      </geometry>
    </visual> 
  </link>

  <gazebo reference="left_front_wheel">
   <material>Gazebo/Green</material>
  </gazebo>

  <gazebo reference="left_back_wheel">
   <material>Gazebo/Green</material>
  </gazebo>

  <gazebo reference="right_front_wheel">
   <material>Gazebo/Green</material>
  </gazebo>
  
  <gazebo reference="right_back_wheel">
   <material>Gazebo/Green</material>
  </gazebo>

  <gazebo reference="chassis">
   <material>Gazebo/Yellow</material>
  </gazebo>

  <gazebo reference="body_part_front">
   <material>Gazebo/Yellow</material>
  </gazebo>

  <gazebo reference="body_part_back">
   <material>Gazebo/Yellow</material>
  </gazebo>

  <gazebo reference="body_part_divider">
   <material>Gazebo/Yellow</material>
  </gazebo>

  <gazebo reference="body_part_roof">
   <material>Gazebo/Yellow</material>
  </gazebo>

  <gazebo reference="camera">
   <material>Gazebo/Blue</material>
  </gazebo>

</robot>
